<?xml version="1.0" encoding="utf-8"?><testsuite errors="0" failures="2" name="pytest" skips="2" tests="6" time="0.097"><testcase classname="app.test.test_demo" file="app/test/test_demo.py" line="7" name="test_demo" time="0.0009610652923583984"></testcase><testcase classname="app.test.test_demo" file="app/test/test_demo.py" line="14" name="test_zero" time="0.0010781288146972656"><failure message="ZeroDivisionError: division by zero">def test_zero():
        &quot;&quot;&quot;
        Test an exception
        &quot;&quot;&quot;
&gt;       _ = 0 / 0
E       ZeroDivisionError: division by zero

app/test/test_demo.py:19: ZeroDivisionError</failure></testcase><testcase classname="app.test.test_demo" file="app/test/test_demo.py" line="21" name="test_skip" time="0.00034809112548828125"><skipped message="Test skipped for reasons." type="pytest.skip">app/test/test_demo.py:21: Test skipped for reasons.</skipped></testcase><testcase classname="app.test.test_demo" file="app/test/test_demo.py" line="29" name="test_nogood" time="0.0016202926635742188"><skipped message="expected test failure"></skipped></testcase><testcase classname="app.test.test_demo" file="app/test/test_demo.py" line="37" name="test_bad_assert" time="0.0006048679351806641"><failure message="assert (1 + 1) == 3">def test_bad_assert():
        &quot;&quot;&quot;
        Test assertion fail
        &quot;&quot;&quot;
&gt;       assert 1 + 1 == 3
E       assert (1 + 1) == 3

```
code snippet
```

app/test/test_demo.py:42: AssertionError</failure></testcase><testcase classname="app.test.test_demo" file="app/test/test_demo.py" line="44" name="test_nofail" time="0.0006163120269775391"></testcase></testsuite>
